Workbook

Sheet README
B2: MSU Sheep Genotyping · tracker
B3: The back end for the producer submission and results pages. One row per record on every tab.
B4: The rows on each tab are example data from the design mock-ups (Prairie Flock, Smith Ranch, Jones Sheep Co). Delete rows 2 and below on every tab except Settings, Conditions and Result_Key before going live. Keep every header row exactly as it is: the web pages and the Apps Script find columns by these names.
B6: Opening this in Google Sheets
B7: Upload the file to Google Drive, right-click it and choose Open with > Google Sheets, then File > Save as Google Sheets. Formulas, dropdowns and colours carry over. The Apps Script is then attached from Extensions > Apps Script in that Google Sheet.
B9: Header colours: who fills each column
B10: Blue | C10: Filled automatically from the producer's submission page by the Apps Script.
B11: Gold | C11: Entered by you or lab staff (receiving, batches, prices, invoice status).
B12: Green | C12: Written by your R pipeline (googlesheets4) after calls are made.
B13: Grey | C13: A formula. Do not type over it. The Apps Script copies these down when it adds a row.
B14: Yellow cell | C14: Needs a value from you before going live (placeholders on Settings).
B16: Tabs
B17: Tab | C17: One row per | D17: What it holds
B18: Settings | C18: setting | D18: Addresses, drop-off hours and contact details used on the pages, packing slip and invoices.
B19: Producers | C19: producer (flock) | D19: Contact details. A returning producer keeps the same Producer_ID.
B20: Submissions | C20: submission form | D20: What the producer sent, consent answers, notes, private link token and where the submission is up to.
B21: Animals | C21: animal on a form | D21: IDs, TSU, breed, birth flock, parentage details and each sample's status. Proven (2+ years at receipt) and the CS_ columns set each animal's cost-share. The receiving page sets Received = Y and Received_By as TSUs are scanned in. Role is optional and not on the form.
B22: Photos | C22: photo | D22: Optional research photos (up to 5 per animal), saved to a Drive folder per submission.
B23: Batches | C23: shipment to the lab | D23: Built on the staff Batches page, which also makes the GenomNZ file. Samples counts originals and replacements.
B24: Replacements | C24: replacement TSU | D24: A new TSU for a failed sample, or a late original, registered by the producer from their results page.
B25: Conditions | C25: condition tested | D25: Name, explanation and whether it shows on the web page. Feeds the Excel "How to read" tab and the PDF.
B26: Result_Key | C26: possible call | D26: Turns a call (RR, 1/3, ...) into the label and colour producers see.
B27: Results | C27: animal x condition | D27: Written by R (push_results): genotype, call, and the label and colour looked up from Result_Key. Released = Y makes it visible.
B28: Parentage | C28: animal with parentage | D28: Written by R (push_parentage): sire and dam results. Released = Y makes it visible.
... B36: Partner_Billing | C36: bill to a partner | D36: One bill per program and period (for example quarterly), totalled from the invoice lines.
B38: IDs
B39: Producer_ID | C39: P003 | D39: One per flock, reused on every submission.
B40: Submission_ID | C40: P003-01 | D40: Producer ID plus that producer's submission number.
B41: Animal_Key | C41: P003-01-26001 | D41: Submission ID plus flock tag, or plus the EID when there is no flock tag (P004-01-840003307300001). Stays the same if the animal is resampled with a new TSU. Results and Parentage rows use this.
B42: Invoice_ID | C42: INV-P003-01 | D42: One invoice per submission.
B43: Private_Link_Token | C43: a3Fh8LwZ0qNe | D43: Random, made by the Apps Script. It is the secret part of the producer's results link.
B45: A submission from start to finish
B46: 1. Submitted | C46: Apps Script | D46: Adds rows to Submissions, Animals and Photos, emails the producer their private link. Status = Submitted.
B47: 2. Box received | C47: You | D47: Scan TSUs in (Received = Y), set Received_Date and Status = Received. The Apps Script creates the invoice with one GENO line counting the TSUs received.
B48: 3. Sent to lab | C48: You | D48: On the staff Batches page, pick the ready samples, download the GenomNZ file, then mark the batch Shipped. Animals get the batch ID and Status = At lab.
B49: 4. Results back | C49: R | D49: push_results() and push_parentage() write the calls with Released = N, add newly genotyped animals to Candidate_Parents, and set Status = Analyzing.
B50: 5. Released | C50: You | D50: Set Released = Y, Results_Released_Date and Status = Results released. The producer's page shows results and they are emailed.
B52: Cost-share invoices
B53: Cost-share is decided per animal. ASI (CS01) covers NSIP animals only: proven animals (2 years and older) in full ($18, producer pays nothing) and animals under 2 partly ($6, producer pays $12). Animals without an NSIP_ID are never covered by ASI. Pick the program in Cost_Share_Program on the producer's Submissions row and the defaults apply to every animal on it.
B54: Exceptions go on the Animals tab: CS_Override_Level (Full, Partial or None) changes one animal, for example an NSIP animal under 2 that ASI covers in full. CS_Override_Program puts one animal under another program, such as a grant (GR01); give it a level too. CS_Program and CS_Level show what will be billed. A program marked Requires_NSIP = Y is never applied to an animal without an NSIP_ID.
...

Sheet Settings
A1: Setting | B1: Value | C1: Notes
A2: Resample_Policy | B2: Replacement TSUs for samples that fail the lab quality check are tested at no charge. | C2: Shown to producers when a TSU fails the lab quality check.
A3: Checks_Payable_To | B3: Montana State University | C3: Printed on invoices.
A4: Mailing_Address | B4: MSU Sheep Genotyping, 311 Animal Biosciences Building, Bozeman, MT 59717 | C4: Printed on the packing slip and invoices.
A5: Dropoff_Location | B5: Montana Wool Lab | C5: Printed on the packing slip.
A6: Dropoff_Hours | B6: M-F 8am-5pm | C6: Printed on the packing slip.
A7: Contact_Email | B7: christian.posbergh@montana.edu | C7: Shown on every page, the packing slip and invoices.
A8: Email_From_Name | B8: MSU Sheep Genotyping | C8: The sender name producers see on every email.
A9: Email_Reply_To | B9: christian.posbergh@montana.edu | C9: Producer replies go here, not to the Gmail account that sends the emails.
A10: Service_Gmail_Address | B10: cposbergh@gmail.com | C10: The Google account that owns this sheet and runs the Apps Script. Emails are sent from it.
A11: Contact_Phone | B11: 406-994-3736
A12: Genotyping_Lab | B12: GenomNZ | C12: Default lab for new batches.
A13: GenomNZ_Birth_Flock | B13: Montana State University | C13: Written in the Birth Flock column of every GenomNZ batch file.
A14: Site_URL | B14: https://cjposbergh.github.io/MSUSheepGenotyping/ | C14: The public website (GitHub Pages). Links in every email start here.
A15: GitHub_Repo | B15: https://github.com/CJPosbergh/MSUSheepGenotyping | C15: Where the website code and README live.
A16: Blank_Submission_Form | B16: https://docs.google.com/spreadsheets/d/1ujVd1LlhDL7ErsTpKPOM78TJuHAzlt2g/edit?usp=drive_link&ouid=110943812388284011858&rtpof=true&sd=true | C16: Download link for the blank Excel submission form, shown on the submission page.
A17: Paper_Consent_Form | B17: https://drive.google.com/file/d/1-h06tVmz_pj5PLaHjtqXAC2T5CFbq6rB/view?usp=drive_link | C17: Linked from the sign page and emails for producers who want to sign on paper.
A18: Proven_Min_Age | B18: 2 | C18: Animals at least this many years old when the box is received count as proven (ASI covers them in full). Age = receipt year minus birth year (earliest year of a range).
A19: Reminder_First_Days | B19: 7 | C19: Days after a box arrives without its signed consent form before the first reminder (email E03).
A20: Reminder_Every_Days | B20: 7 | C20: Days between reminders.
A21: Reminder_Max | B21: 3 | C21: Most reminders sent for one submission.
A22: Root_Folder_ID | C22: Filled in by Genotyping > Set up (the "MSU Sheep Genotyping" Drive folder).
A23: Submissions_Folder_ID | C23: Filled in by Genotyping > Set up.
A24: Batches_Folder_ID | C24: Filled in by Genotyping > Set up.
A25: Partner_Bills_Folder_ID | C25: Filled in by Genotyping > Set up.
A26: Templates_Folder_ID | C26: Filled in by Genotyping > Set up.
A27: Invoice_Template_ID | C27: Filled in by Genotyping > Set up (a Google Doc you can edit).
A28: Partner_Bill_Template_ID | C28: Filled in by Genotyping > Set up (a Google Doc you can edit).
A29: Web_App_URL | C29: The Apps Script web app address, for reference. The website reads it from assets/js/config.js.
A30: Staff_Passphrase | C30: Unlocks the staff receiving and batches pages. Type it here in your own copy of the tracker only: this file is public in the GitHub repo, so leave it blank there. Checked by the Apps Script only; never put it in the web page code. The staff pages stay locked while this is blank.

Sheet Producers
A1: Producer_ID | B1: Flock_Name | C1: Contact_Name | D1: Email | E1: Phone | F1: Mailing_Address | G1: NSIP_Flock_ID | H1: First_Submitted | I1: Submissions | J1: Notes
A2: P002 | B2: Prairie Flock | C2: Pat Nolan | D2: pat@prairieflock.example.com | E2: 406-555-0150 | F2: Box 22, Harlowton MT | H2: 46296 | I2: =COUNTIF(Submissions!B:B,A2)
A3: P003 | B3: Smith Ranch | C3: Jane Smith | D3: jane.smith@example.com | E3: 406-555-0101 | F3: 12 Ranch Rd, Big Timber MT | G3: 6100 | H3: 46296 | I3: =COUNTIF(Submissions!B:B,A3)
A4: P004 | B4: Jones Sheep Co | C4: Bob Jones | D4: bob@jonessheep.example.com | E4: 406-555-0199 | F4: PO Box 4, Dillon MT | H4: 46296 | I4: =COUNTIF(Submissions!B:B,A4)

Sheet Submissions
A1: Submission_ID | B1: Producer_ID | C1: Flock_Name | D1: Submitted_Date | E1: Breed | F1: NSIP_Animals | G1: Research_Use | H1: Signed_By | I1: Signed_Date | J1: Producer_Notes | K1: Form_File | L1: Private_Link_Token | M1: Animals_Listed | N1: TSUs_Received | O1: Photos | P1: Status | Q1: Received_Date | R1: Results_Released_Date | S1: Invoice_ID | T1: Staff_Notes | U1: Cost_Share_Program | V1: Signature_Method | W1: Research_Withdrawn_Date | X1: Drive_Folder | Y1: Results_PDF | Z1: Results_Excel | AA1: Reminders_Sent | AB1: Last_Reminder_Date | AC1: Contact_On_Form
A2: P002-01 | B2: P002 | C2: =IFERROR(INDEX(Producers!B:B,MATCH(B2,Producers!A:A,0))&"","") | D2: 46296 | E2: Hampshire | F2: =COUNTIFS(Animals!B:B,A2,Animals!E:E,"<>") | G2: Y | H2: Pat Nolan | I2: 46296 | K2: [Drive link] | L2: k7Qm2xR9vTp4 | M2: =COUNTIF(Animals!B:B,A2) | N2: =COUNTIFS(Animals!B:B,A2,Animals!N:N,"Y") | O2: =COUNTIF(Photos!B:B,A2) | P2: At lab | Q2: 46298 | S2: =IF(Q2="","","INV-"&A2) | U2: CS01 | V2: Paper | X2: [Drive link] | AA2: 0
A3: P003-01 | B3: P003 | C3: =IFERROR(INDEX(Producers!B:B,MATCH(B3,Producers!A:A,0))&"","") | D3: 46296 | E3: Targhee | F3: =COUNTIFS(Animals!B:B,A3,Animals!E:E,"<>") | G3: Y | H3: Jane Smith | I3: 46296 | J3: Please check parentage against 23015. | K3: [Drive link] | L3: a3Fh8LwZ0qNe | M3: =COUNTIF(Animals!B:B,A3) | N3: =COUNTIFS(Animals!B:B,A3,Animals!N:N,"Y") | O3: =COUNTIF(Photos!B:B,A3) | P3: Results released | Q3: 46301 | R3: 46323 | S3: =IF(Q3="","","INV-"&A3) | V3: Online | X3: [Drive link] | AA3: 0
A4: P004-01 | B4: P004 | C4: =IFERROR(INDEX(Producers!B:B,MATCH(B4,Producers!A:A,0))&"","") | D4: 46296 | E4: Columbia | F4: =COUNTIFS(Animals!B:B,A4,Animals!E:E,"<>") | G4: Y | H4: Bob Jones | I4: 46296 | K4: [Drive link] | L4: Xc5bT1uJ6sDy | M4: =COUNTIF(Animals!B:B,A4) | N4: =COUNTIFS(Animals!B:B,A4,Animals!N:N,"Y") | O4: =COUNTIF(Photos!B:B,A4) | P4: Submitted | S4: =IF(Q4="","","INV-"&A4) | V4: Online | X4: [Drive link] | AA4: 0

Sheet Animals
A1: Animal_Key | B1: Submission_ID | C1: Flock_Tag | D1: EID | E1: NSIP_ID | F1: TSU_Barcode | G1: Sex | H1: Year_of_Birth | I1: Role | J1: Reported_Sire | K1: Reported_Dam | L1: Test_Conditions | M1: Test_Parentage | N1: Received | O1: Batch | P1: Sample_Status | Q1: Replaced_TSU | R1: Photos | S1: Notes | T1: Received_By | U1: Producer_ID | V1: Genotyped | W1: Reported_Sire_Status | X1: Reported_Dam_Status | Y1: Breed | Z1: Birth_Flock | AA1: Age_At_Receipt | AB1: Proven | AC1: CS_Override_Program | AD1: CS_Override_Level | AE1: CS_Program | AF1: CS_Level | AG1: Billed_On
A2: P002-01-PF01 | B2: P002-01 | C2: PF01 | D2: 840003307400001 | E2: 610014202225PF01 | F2: NE05200301 | G2: F | H2: 2022 | I2: Other | L2: Y | M2: N | N2: Y | O2: B2026-02 | P2: At lab | R2: =COUNTIF(Photos!A:A,A2) | T2: [Staff name] | U2: =IFERROR(INDEX(Submissions!B:B,MATCH(B2,Submissions!A:A,0))&"","") | V2: =IF(P2="Complete","Y","N") | W2: =IF(J2="","",IF(COUNTIFS(Candidate_Parents!A:A,U2,Candidate_Parents!C:C,J2)+COUNTIFS(Candidate_Parents!A:A,U2,Candidate_Parents!D:D,J2)+COUNTIFS(Candidate_Parents!A:A,U2,Candidate_Parents!E:E,J2)>0,"Genotyped",IF(COUNTIFS(B:B,B2,C:C,J2,P:P,"<>Not received")>0,"In this submission","Not genotyped"))) | X2: =IF(K2="","",IF(COUNTIFS(Candidate_Parents!A:A,U2,Candidate_Parents!C:C,K2)+COUNTIFS(Candidate_Parents!A:A,U2,Candidate_Parents!D:D,K2)+COUNTIFS(Candidate_Parents!A:A,U2,Candidate_Parents!E:E,K2)>0,"Genotyped",IF(COUNTIFS(B:B,B2,C:C,K2,P:P,"<>Not received")>0,"In this submission","Not genotyped"))) | Y2: Hampshire | Z2: Prairie Flock | AA2: =IF(H2="","",IFERROR(YEAR(IF(INDEX(Submissions!Q:Q,MATCH(B2,Submissions!A:A,0))="",TODAY(),INDEX(Submissions!Q:Q,MATCH(B2,Submissions!A:A,0))))-VALUE(LEFT(H2,4)),"")) | AB2: =IF(AA2="","",IF(AA2>=INDEX(Settings!B:B,MATCH("Proven_Min_Age",Settings!A:A,0)),"Y","N")) | AE2: =IF(IF(AC2<>"",AC2,IFERROR(INDEX(Submissions!U:U,MATCH(B2,Submissions!A:A,0))&"",""))="","",IF(AND(IFERROR(INDEX(Cost_Share!H:H,MATCH(IF(AC2<>"",AC2,IFERROR(INDEX(Submissions!U:U,MATCH(B2,Submissions!A:A,0))&"","")),Cost_Share!A:A,0))&"","")="Y",E2=""),"",IF(AC2<>"",AC2,IFERROR(INDEX(Submissions!U:U,MATCH(B2,Submissions!A:A,0))&"","")))) | AF2: =IF(AE2="","None",IF(AD2<>"",AD2,IF(AB2="Y","Full","Partial"))) | AG2: INV-P002-01
A3: P002-01-PF02 | B3: P002-01 | C3: PF02 | D3: 840003307400002 | E3: 610014202225PF02 | F3: NE05200302 | G3: M | H3: 2023 | I3: Other | L3: Y | M3: N | N3: Y | O3: B2026-02 | P3: At lab | R3: =COUNTIF(Photos!A:A,A3) | T3: [Staff name] | U3: =IFERROR(INDEX(Submissions!B:B,MATCH(B3,Submissions!A:A,0))&"","") | V3: =IF(P3="Complete","Y","N") | W3: =IF(J3="","",IF(COUNTIFS(Candidate_Parents!A:A,U3,Candidate_Parents!C:C,J3)+COUNTIFS(Candidate_Parents!A:A,U3,Candidate_Parents!D:D,J3)+COUNTIFS(Candidate_Parents!A:A,U3,Candidate_Parents!E:E,J3)>0,"Genotyped",IF(COUNTIFS(B:B,B3,C:C,J3,P:P,"<>Not received")>0,"In this submission","Not genotyped"))) | X3: =IF(K3="","",IF(COUNTIFS(Candidate_Parents!A:A,U3,Candidate_Parents!C:C,K3)+COUNTIFS(Candidate_Parents!A:A,U3,Candidate_Parents!D:D,K3)+COUNTIFS(Candidate_Parents!A:A,U3,Candidate_Parents!E:E,K3)>0,"Genotyped",IF(COUNTIFS(B:B,B3,C:C,K3,P:P,"<>Not received")>0,"In this submission","Not genotyped"))) | Y3: Hampshire | Z3: Prairie Flock | AA3: =IF(H3="","",IFERROR(YEAR(IF(INDEX(Submissions!Q:Q,MATCH(B3,Submissions!A:A,0))="",TODAY(),INDEX(Submissions!Q:Q,MATCH(B3,Submissions!A:A,0))))-VALUE(LEFT(H3,4)),"")) | AB3: =IF(AA3="","",IF(AA3>=INDEX(Settings!B:B,MATCH("Proven_Min_Age",Settings!A:A,0)),"Y","N")) | AE3: =IF(IF(AC3<>"",AC3,IFERROR(INDEX(Submissions!U:U,MATCH(B3,Submissions!A:A,0))&"",""))="","",IF(AND(IFERROR(INDEX(Cost_Share!H:H,MATCH(IF(AC3<>"",AC3,IFERROR(INDEX(Submissions!U:U,MATCH(B3,Submissions!A:A,0))&"","")),Cost_Share!A:A,0))&"","")="Y",E3=""),"",IF(AC3<>"",AC3,IFERROR(INDEX(Submissions!U:U,MATCH(B3,Submissions!A:A,0))&"","")))) | AF3: =IF(AE3="","None",IF(AD3<>"",AD3,IF(AB3="Y","Full","Partial"))) | AG3: INV-P002-01
A4: P002-01-PF03 | B4: P002-01 | C4: PF03 | D4: 840003307400003 | E4: 610014202325PF03 | F4: NE05200303 | G4: F | H4: 2025 | I4: Other | L4: Y | M4: N | N4: Y | O4: B2026-02 | P4: At lab | R4: =COUNTIF(Photos!A:A,A4) | T4: [Staff name] | U4: =IFERROR(INDEX(Submissions!B:B,MATCH(B4,Submissions!A:A,0))&"","") | V4: =IF(P4="Complete","Y","N") | W4: =IF(J4="","",IF(COUNTIFS(Candidate_Parents!A:A,U4,Candidate_Parents!C:C,J4)+COUNTIFS(Candidate_Parents!A:A,U4,Candidate_Parents!D:D,J4)+COUNTIFS(Candidate_Parents!A:A,U4,Candidate_Parents!E:E,J4)>0,"Genotyped",IF(COUNTIFS(B:B,B4,C:C,J4,P:P,"<>Not received")>0,"In this submission","Not genotyped"))) | X4: =IF(K4="","",IF(COUNTIFS(Candidate_Parents!A:A,U4,Candidate_Parents!C:C,K4)+COUNTIFS(Candidate_Parents!A:A,U4,Candidate_Parents!D:D,K4)+COUNTIFS(Candidate_Parents!A:A,U4,Candidate_Parents!E:E,K4)>0,"Genotyped",IF(COUNTIFS(B:B,B4,C:C,K4,P:P,"<>Not received")>0,"In this submission","Not genotyped"))) | Y4: Hampshire | Z4: Prairie Flock | AA4: =IF(H4="","",IFERROR(YEAR(IF(INDEX(Submissions!Q:Q,MATCH(B4,Submissions!A:A,0))="",TODAY(),INDEX(Submissions!Q:Q,MATCH(B4,Submissions!A:A,0))))-VALUE(LEFT(H4,4)),"")) | AB4: =IF(AA4="","",IF(AA4>=INDEX(Settings!B:B,MATCH("Proven_Min_Age",Settings!A:A,0)),"Y","N")) | AE4: =IF(IF(AC4<>"",AC4,IFERROR(INDEX(Submissions!U:U,MATCH(B4,Submissions!A:A,0))&"",""))="","",IF(AND(IFERROR(INDEX(Cost_Share!H:H,MATCH(IF(AC4<>"",AC4,IFERROR(INDEX(Submissions!U:U,MATCH(B4,Submissions!A:A,0))&"","")),Cost_Share!A:A,0))&"","")="Y",E4=""),"",IF(AC4<>"",AC4,IFERROR(INDEX(Submissions!U:U,MATCH(B4,Submissions!A:A,0))&"","")))) | AF4: =IF(AE4="","None",IF(AD4<>"",AD4,IF(AB4="Y","Full","Partial"))) | AG4: INV-P002-01
A5: P002-01-PF04 | B5: P002-01 | C5: PF04 | D5: 840003307400004 | E5: 610014202325PF04 | F5: NE05200304 | G5: M | H5: 2025 | I5: Other | L5: Y | M5: N | N5: Y | O5: B2026-02 | P5: At lab | R5: =COUNTIF(Photos!A:A,A5) | T5: [Staff name] | U5: =IFERROR(INDEX(Submissions!B:B,MATCH(B5,Submissions!A:A,0))&"","") | V5: =IF(P5="Complete","Y","N") | W5: =IF(J5="","",IF(COUNTIFS(Candidate_Parents!A:A,U5,Candidate_Parents!C:C,J5)+COUNTIFS(Candidate_Parents!A:A,U5,Candidate_Parents!D:D,J5)+COUNTIFS(Candidate_Parents!A:A,U5,Candidate_Parents!E:E,J5)>0,"Genotyped",IF(COUNTIFS(B:B,B5,C:C,J5,P:P,"<>Not received")>0,"In this submission","Not genotyped"))) | X5: =IF(K5="","",IF(COUNTIFS(Candidate_Parents!A:A,U5,Candidate_Parents!C:C,K5)+COUNTIFS(Candidate_Parents!A:A,U5,Candidate_Parents!D:D,K5)+COUNTIFS(Candidate_Parents!A:A,U5,Candidate_Parents!E:E,K5)>0,"Genotyped",IF(COUNTIFS(B:B,B5,C:C,K5,P:P,"<>Not received")>0,"In this submission","Not genotyped"))) | Y5: Hampshire | Z5: Prairie Flock | AA5: =IF(H5="","",IFERROR(YEAR(IF(INDEX(Submissions!Q:Q,MATCH(B5,Submissions!A:A,0))="",TODAY(),INDEX(Submissions!Q:Q,MATCH(B5,Submissions!A:A,0))))-VALUE(LEFT(H5,4)),"")) | AB5: =IF(AA5="","",IF(AA5>=INDEX(Settings!B:B,MATCH("Proven_Min_Age",Settings!A:A,0)),"Y","N")) | AD5: Full | AE5: =IF(IF(AC5<>"",AC5,IFERROR(INDEX(Submissions!U:U,MATCH(B5,Submissions!A:A,0))&"",""))="","",IF(AND(IFERROR(INDEX(Cost_Share!H:H,MATCH(IF(AC5<>"",AC5,IFERROR(INDEX(Submissions!U:U,MATCH(B5,Submissions!A:A,0))&"","")),Cost_Share!A:A,0))&"","")="Y",E5=""),"",IF(AC5<>"",AC5,IFERROR(INDEX(Submissions!U:U,MATCH(B5,Submissions!A:A,0))&"","")))) | AF5: =IF(AE5="","None",IF(AD5<>"",AD5,IF(AB5="Y","Full","Partial"))) | AG5: INV-P002-01
A6: P002-01-PF05 | B6: P002-01 | C6: PF05 | D6: 840003307400005 | F6: NE05200305 | G6: F | H6: 2025 | I6: Other | L6: Y | M6: N | N6: Y | O6: B2026-02 | P6: At lab | R6: =COUNTIF(Photos!A:A,A6) | T6: [Staff name] | U6: =IFERROR(INDEX(Submissions!B:B,MATCH(B6,Submissions!A:A,0))&"","") | V6: =IF(P6="Complete","Y","N") | W6: =IF(J6="","",IF(COUNTIFS(Candidate_Parents!A:A,U6,Candidate_Parents!C:C,J6)+COUNTIFS(Candidate_Parents!A:A,U6,Candidate_Parents!D:D,J6)+COUNTIFS(Candidate_Parents!A:A,U6,Candidate_Parents!E:E,J6)>0,"Genotyped",IF(COUNTIFS(B:B,B6,C:C,J6,P:P,"<>Not received")>0,"In this submission","Not genotyped"))) | X6: =IF(K6="","",IF(COUNTIFS(Candidate_Parents!A:A,U6,Candidate_Parents!C:C,K6)+COUNTIFS(Candidate_Parents!A:A,U6,Candidate_Parents!D:D,K6)+COUNTIFS(Candidate_Parents!A:A,U6,Candidate_Parents!E:E,K6)>0,"Genotyped",IF(COUNTIFS(B:B,B6,C:C,K6,P:P,"<>Not received")>0,"In this submission","Not genotyped"))) | Y6: Hampshire | Z6: Prairie Flock | AA6: =IF(H6="","",IFERROR(YEAR(IF(INDEX(Submissions!Q:Q,MATCH(B6,Submissions!A:A,0))="",TODAY(),INDEX(Submissions!Q:Q,MATCH(B6,Submissions!A:A,0))))-VALUE(LEFT(H6,4)),"")) | AB6: =IF(AA6="","",IF(AA6>=INDEX(Settings!B:B,MATCH("Proven_Min_Age",Settings!A:A,0)),"Y","N")) | AC6: GR01 | AD6: Full | AE6: =IF(IF(AC6<>"",AC6,IFERROR(INDEX(Submissions!U:U,MATCH(B6,Submissions!A:A,0))&"",""))="","",IF(AND(IFERROR(INDEX(Cost_Share!H:H,MATCH(IF(AC6<>"",AC6,IFERROR(INDEX(Submissions!U:U,MATCH(B6,Submissions!A:A,0))&"","")),Cost_Share!A:A,0))&"","")="Y",E6=""),"",IF(AC6<>"",AC6,IFERROR(INDEX(Submissions!U:U,MATCH(B6,Submissions!A:A,0))&"","")))) | AF6: =IF(AE6="","None",IF(AD6<>"",AD6,IF(AB6="Y","Full","Partial"))) | AG6: INV-P002-01
A7: P003-01-26001 | B7: P003-01 | C7: 26001 | D7: 840003307100001 | E7: 610014202626T001 | F7: NE05200001 | G7: M | H7: 2026 | I7: Offspring | J7: 23015 | L7: Y | M7: Y | N7: Y | O7: B2026-01 | P7: Complete | R7: =COUNTIF(Photos!A:A,A7) | T7: [Staff name] | U7: =IFERROR(INDEX(Submissions!B:B,MATCH(B7,Submissions!A:A,0))&"","") | V7: =IF(P7="Complete","Y","N") | W7: =IF(J7="","",IF(COUNTIFS(Candidate_Parents!A:A,U7,Candidate_Parents!C:C,J7)+COUNTIFS(Candidate_Parents!A:A,U7,Candidate_Parents!D:D,J7)+COUNTIFS(Candidate_Parents!A:A,U7,Candidate_Parents!E:E,J7)>0,"Genotyped",IF(COUNTIFS(B:B,B7,C:C,J7,P:P,"<>Not received")>0,"In this submission","Not genotyped"))) | X7: =IF(K7="","",IF(COUNTIFS(Candidate_Parents!A:A,U7,Candidate_Parents!C:C,K7)+COUNTIFS(Candidate_Parents!A:A,U7,Candidate_Parents!D:D,K7)+COUNTIFS(Candidate_Parents!A:A,U7,Candidate_Parents!E:E,K7)>0,"Genotyped",IF(COUNTIFS(B:B,B7,C:C,K7,P:P,"<>Not received")>0,"In this submission","Not genotyped"))) | Y7: Targhee | Z7: Smith Ranch | AA7: =IF(H7="","",IFERROR(YEAR(IF(INDEX(Submissions!Q:Q,MATCH(B7,Submissions!A:A,0))="",TODAY(),INDEX(Submissions!Q:Q,MATCH(B7,Submissions!A:A,0))))-VALUE(LEFT(H7,4)),"")) | AB7: =IF(AA7="","",IF(AA7>=INDEX(Settings!B:B,MATCH("Proven_Min_Age",Settings!A:A,0)),"Y","N")) | AE7: =IF(IF(AC7<>"",AC7,IFERROR(INDEX(Submissions!U:U,MATCH(B7,Submissions!A:A,0))&"",""))="","",IF(AND(IFERROR(INDEX(Cost_Share!H:H,MATCH(IF(AC7<>"",AC7,IFERROR(INDEX(Submissions!U:U,MATCH(B7,Submissions!A:A,0))&"","")),Cost_Share!A:A,0))&"","")="Y",E7=""),"",IF(AC7<>"",AC7,IFERROR(INDEX(Submissions!U:U,MATCH(B7,Submissions!A:A,0))&"","")))) | AF7: =IF(AE7="","None",IF(AD7<>"",AD7,IF(AB7="Y","Full","Partial"))) | AG7: INV-P003-01
A8: P003-01-26002 | B8: P003-01 | C8: 26002 | D8: 840003307100002 | E8: 610014202626T002 | F8: NE05200002 | G8: F | H8: 2026 | I8: Offspring | J8: 23015 | L8: Y | M8: Y | N8: Y | O8: B2026-01 | P8: Complete | R8: =COUNTIF(Photos!A:A,A8) | T8: [Staff name] | U8: =IFERROR(INDEX(Submissions!B:B,MATCH(B8,Submissions!A:A,0))&"","") | V8: =IF(P8="Complete","Y","N") | W8: =IF(J8="","",IF(COUNTIFS(Candidate_Parents!A:A,U8,Candidate_Parents!C:C,J8)+COUNTIFS(Candidate_Parents!A:A,U8,Candidate_Parents!D:D,J8)+COUNTIFS(Candidate_Parents!A:A,U8,Candidate_Parents!E:E,J8)>0,"Genotyped",IF(COUNTIFS(B:B,B8,C:C,J8,P:P,"<>Not received")>0,"In this submission","Not genotyped"))) | X8: =IF(K8="","",IF(COUNTIFS(Candidate_Parents!A:A,U8,Candidate_Parents!C:C,K8)+COUNTIFS(Candidate_Parents!A:A,U8,Candidate_Parents!D:D,K8)+COUNTIFS(Candidate_Parents!A:A,U8,Candidate_Parents!E:E,K8)>0,"Genotyped",IF(COUNTIFS(B:B,B8,C:C,K8,P:P,"<>Not received")>0,"In this submission","Not genotyped"))) | Y8: Targhee | Z8: Smith Ranch | AA8: =IF(H8="","",IFERROR(YEAR(IF(INDEX(Submissions!Q:Q,MATCH(B8,Submissions!A:A,0))="",TODAY(),INDEX(Submissions!Q:Q,MATCH(B8,Submissions!A:A,0))))-VALUE(LEFT(H8,4)),"")) | AB8: =IF(AA8="","",IF(AA8>=INDEX(Settings!B:B,MATCH("Proven_Min_Age",Settings!A:A,0)),"Y","N")) | AE8: =IF(IF(AC8<>"",AC8,IFERROR(INDEX(Submissions!U:U,MATCH(B8,Submissions!A:A,0))&"",""))="","",IF(AND(IFERROR(INDEX(Cost_Share!H:H,MATCH(IF(AC8<>"",AC8,IFERROR(INDEX(Submissions!U:U,MATCH(B8,Submissions!A:A,0))&"","")),Cost_Share!A:A,0))&"","")="Y",E8=""),"",IF(AC8<>"",AC8,IFERROR(INDEX(Submissions!U:U,MATCH(B8,Submissions!A:A,0))&"","")))) | AF8: =IF(AE8="","None",IF(AD8<>"",AD8,IF(AB8="Y","Full","Partial"))) | AG8: INV-P003-01
A9: P003-01-26003 | B9: P003-01 | C9: 26003 | D9: 840003307100003 | E9: 610014202626T003 | F9: NE05200003 | G9: M | H9: 2026 | I9: Offspring | J9: 23015 | L9: Y | M9: Y | N9: Y | O9: B2026-01 | P9: Complete | R9: =COUNTIF(Photos!A:A,A9) | T9: [Staff name] | U9: =IFERROR(INDEX(Submissions!B:B,MATCH(B9,Submissions!A:A,0))&"","") | V9: =IF(P9="Complete","Y","N") | W9: =IF(J9="","",IF(COUNTIFS(Candidate_Parents!A:A,U9,Candidate_Parents!C:C,J9)+COUNTIFS(Candidate_Parents!A:A,U9,Candidate_Parents!D:D,J9)+COUNTIFS(Candidate_Parents!A:A,U9,Candidate_Parents!E:E,J9)>0,"Genotyped",IF(COUNTIFS(B:B,B9,C:C,J9,P:P,"<>Not received")>0,"In this submission","Not genotyped"))) | X9: =IF(K9="","",IF(COUNTIFS(Candidate_Parents!A:A,U9,Candidate_Parents!C:C,K9)+COUNTIFS(Candidate_Parents!A:A,U9,Candidate_Parents!D:D,K9)+COUNTIFS(Candidate_Parents!A:A,U9,Candidate_Parents!E:E,K9)>0,"Genotyped",IF(COUNTIFS(B:B,B9,C:C,K9,P:P,"<>Not received")>0,"In this submission","Not genotyped"))) | Y9: Targhee | Z9: Smith Ranch | AA9: =IF(H9="","",IFERROR(YEAR(IF(INDEX(Submissions!Q:Q,MATCH(B9,Submissions!A:A,0))="",TODAY(),INDEX(Submissions!Q:Q,MATCH(B9,Submissions!A:A,0))))-VALUE(LEFT(H9,4)),"")) | AB9: =IF(AA9="","",IF(AA9>=INDEX(Settings!B:B,MATCH("Proven_Min_Age",Settings!A:A,0)),"Y","N")) | AE9: =IF(IF(AC9<>"",AC9,IFERROR(INDEX(Submissions!U:U,MATCH(B9,Submissions!A:A,0))&"",""))="","",IF(AND(IFERROR(INDEX(Cost_Share!H:H,MATCH(IF(AC9<>"",AC9,IFERROR(INDEX(Submissions!U:U,MATCH(B9,Submissions!A:A,0))&"","")),Cost_Share!A:A,0))&"","")="Y",E9=""),"",IF(AC9<>"",AC9,IFERROR(INDEX(Submissions!U:U,MATCH(B9,Submissions!A:A,0))&"","")))) | AF9: =IF(AE9="","None",IF(AD9<>"",AD9,IF(AB9="Y","Full","Partial"))) | AG9: INV-P003-01
A10: P003-01-26004 | B10: P003-01 | C10: 26004 | D10: 840003307100004 | E10: 610014202626T004 | F10: NE05200004 | G10: F | H10: 2026 | I10: Offspring | J10: 23015 | L10: Y | M10: Y | N10: Y | O10: B2026-01 | P10: Complete | R10: =COUNTIF(Photos!A:A,A10) | T10: [Staff name] | U10: =IFERROR(INDEX(Submissions!B:B,MATCH(B10,Submissions!A:A,0))&"","") | V10: =IF(P10="Complete","Y","N") | W10: =IF(J10="","",IF(COUNTIFS(Candidate_Parents!A:A,U10,Candidate_Parents!C:C,J10)+COUNTIFS(Candidate_Parents!A:A,U10,Candidate_Parents!D:D,J10)+COUNTIFS(Candidate_Parents!A:A,U10,Candidate_Parents!E:E,J10)>0,"Genotyped",IF(COUNTIFS(B:B,B10,C:C,J10,P:P,"<>Not received")>0,"In this submission","Not genotyped"))) | X10: =IF(K10="","",IF(COUNTIFS(Candidate_Parents!A:A,U10,Candidate_Parents!C:C,K10)+COUNTIFS(Candidate_Parents!A:A,U10,Candidate_Parents!D:D,K10)+COUNTIFS(Candidate_Parents!A:A,U10,Candidate_Parents!E:E,K10)>0,"Genotyped",IF(COUNTIFS(B:B,B10,C:C,K10,P:P,"<>Not received")>0,"In this submission","Not genotyped"))) | Y10: Targhee | Z10: Smith Ranch | AA10: =IF(H10="","",IFERROR(YEAR(IF(INDEX(Submissions!Q:Q,MATCH(B10,Submissions!A:A,0))="",TODAY(),INDEX(Submissions!Q:Q,MATCH(B10,Submissions!A:A,0))))-VALUE(LEFT(H10,4)),"")) | AB10: =IF(AA10="","",IF(AA10>=INDEX(Settings!B:B,MATCH("Proven_Min_Age",Settings!A:A,0)),"Y","N")) | AE10: =IF(IF(AC10<>"",AC10,IFERROR(INDEX(Submissions!U:U,MATCH(B10,Submissions!A:A,0))&"",""))="","",IF(AND(IFERROR(INDEX(Cost_Share!H:H,MATCH(IF(AC10<>"",AC10,IFERROR(INDEX(Submissions!U:U,MATCH(B10,Submissions!A:A,0))&"","")),Cost_Share!A:A,0))&"","")="Y",E10=""),"",IF(AC10<>"",AC10,IFERROR(INDEX(Submissions!U:U,MATCH(B10,Submissions!A:A,0))&"","")))) | AF10: =IF(AE10="","None",IF(AD10<>"",AD10,IF(AB10="Y","Full","Partial"))) | AG10: INV-P003-01
A11: P003-01-26005 | B11: P003-01 | C11: 26005 | D11: 840003307100005 | E11: 610014202626T005 | F11: NE05200005 | G11: M | H11: 2026 | I11: Offspring | J11: 23015 | L11: Y | M11: Y | N11: Y | O11: B2026-01 | P11: Complete | R11: =COUNTIF(Photos!A:A,A11) | T11: [Staff name] | U11: =IFERROR(INDEX(Submissions!B:B,MATCH(B11,Submissions!A:A,0))&"","") | V11: =IF(P11="Complete","Y","N") | W11: =IF(J11="","",IF(COUNTIFS(Candidate_Parents!A:A,U11,Candidate_Parents!C:C,J11)+COUNTIFS(Candidate_Parents!A:A,U11,Candidate_Parents!D:D,J11)+COUNTIFS(Candidate_Parents!A:A,U11,Candidate_Parents!E:E,J11)>0,"Genotyped",IF(COUNTIFS(B:B,B11,C:C,J11,P:P,"<>Not received")>0,"In this submission","Not genotyped"))) | X11: =IF(K11="","",IF(COUNTIFS(Candidate_Parents!A:A,U11,Candidate_Parents!C:C,K11)+COUNTIFS(Candidate_Parents!A:A,U11,Candidate_Parents!D:D,K11)+COUNTIFS(Candidate_Parents!A:A,U11,Candidate_Parents!E:E,K11)>0,"Genotyped",IF(COUNTIFS(B:B,B11,C:C,K11,P:P,"<>Not received")>0,"In this submission","Not genotyped"))) | Y11: Targhee | Z11: Smith Ranch | AA11: =IF(H11="","",IFERROR(YEAR(IF(INDEX(Submissions!Q:Q,MATCH(B11,Submissions!A:A,0))="",TODAY(),INDEX(Submissions!Q:Q,MATCH(B11,Submissions!A:A,0))))-VALUE(LEFT(H11,4)),"")) | AB11: =IF(AA11="","",IF(AA11>=INDEX(Settings!B:B,MATCH("Proven_Min_Age",Settings!A:A,0)),"Y","N")) | AE11: =IF(IF(AC11<>"",AC11,IFERROR(INDEX(Submissions!U:U,MATCH(B11,Submissions!A:A,0))&"",""))="","",IF(AND(IFERROR(INDEX(Cost_Share!H:H,MATCH(IF(AC11<>"",AC11,IFERROR(INDEX(Submissions!U:U,MATCH(B11,Submissions!A:A,0))&"","")),Cost_Share!A:A,0))&"","")="Y",E11=""),"",IF(AC11<>"",AC11,IFERROR(INDEX(Submissions!U:U,MATCH(B11,Submissions!A:A,0))&"","")))) | AF11: =IF(AE11="","None",IF(AD11<>"",AD11,IF(AB11="Y","Full","Partial"))) | AG11: INV-P003-01
A12: P003-01-26006 | B12: P003-01 | C12: 26006 | D12: 840003307100006 | E12: 610014202626T006 | F12: NE05200006 | G12: F | H12: 2026 | I12: Offspring | J12: 23015 | L12: Y | M12: Y | N12: Y | O12: B2026-01 | P12: Complete | R12: =COUNTIF(Photos!A:A,A12) | T12: [Staff name] | U12: =IFERROR(INDEX(Submissions!B:B,MATCH(B12,Submissions!A:A,0))&"","") | V12: =IF(P12="Complete","Y","N") | W12: =IF(J12="","",IF(COUNTIFS(Candidate_Parents!A:A,U12,Candidate_Parents!C:C,J12)+COUNTIFS(Candidate_Parents!A:A,U12,Candidate_Parents!D:D,J12)+COUNTIFS(Candidate_Parents!A:A,U12,Candidate_Parents!E:E,J12)>0,"Genotyped",IF(COUNTIFS(B:B,B12,C:C,J12,P:P,"<>Not received")>0,"In this submission","Not genotyped"))) | X12: =IF(K12="","",IF(COUNTIFS(Candidate_Parents!A:A,U12,Candidate_Parents!C:C,K12)+COUNTIFS(Candidate_Parents!A:A,U12,Candidate_Parents!D:D,K12)+COUNTIFS(Candidate_Parents!A:A,U12,Candidate_Parents!E:E,K12)>0,"Genotyped",IF(COUNTIFS(B:B,B12,C:C,K12,P:P,"<>Not received")>0,"In this submission","Not genotyped"))) | Y12: Targhee | Z12: Smith Ranch | AA12: =IF(H12="","",IFERROR(YEAR(IF(INDEX(Submissions!Q:Q,MATCH(B12,Submissions!A:A,0))="",TODAY(),INDEX(Submissions!Q:Q,MATCH(B12,Submissions!A:A,0))))-VALUE(LEFT(H12,4)),"")) | AB12: =IF(AA12="","",IF(AA12>=INDEX(Settings!B:B,MATCH("Proven_Min_Age",Settings!A:A,0)),"Y","N")) | AE12: =IF(IF(AC12<>"",AC12,IFERROR(INDEX(Submissions!U:U,MATCH(B12,Submissions!A:A,0))&"",""))="","",IF(AND(IFERROR(INDEX(Cost_Share!H:H,MATCH(IF(AC12<>"",AC12,IFERROR(INDEX(Submissions!U:U,MATCH(B12,Submissions!A:A,0))&"","")),Cost_Share!A:A,0))&"","")="Y",E12=""),"",IF(AC12<>"",AC12,IFERROR(INDEX(Submissions!U:U,MATCH(B12,Submissions!A:A,0))&"","")))) | AF12: =IF(AE12="","None",IF(AD12<>"",AD12,IF(AB12="Y","Full","Partial"))) | AG12: INV-P003-01
A13: P003-01-26007 | B13: P003-01 | C13: 26007 | D13: 840003307100007 | E13: 610014202626T007 | F13: NE05200099 | G13: M | H13: 2026 | I13: Offspring | J13: 23015 | L13: Y | M13: Y | N13: Y | P13: Awaiting replacement | Q13: NE05200007 | R13: =COUNTIF(Photos!A:A,A13) | S13: Replacement P003-01-R1 on its way | T13: [Staff name] | U13: =IFERROR(INDEX(Submissions!B:B,MATCH(B13,Submissions!A:A,0))&"","") | V13: =IF(P13="Complete","Y","N") | W13: =IF(J13="","",IF(COUNTIFS(Candidate_Parents!A:A,U13,Candidate_Parents!C:C,J13)+COUNTIFS(Candidate_Parents!A:A,U13,Candidate_Parents!D:D,J13)+COUNTIFS(Candidate_Parents!A:A,U13,Candidate_Parents!E:E,J13)>0,"Genotyped",IF(COUNTIFS(B:B,B13,C:C,J13,P:P,"<>Not received")>0,"In this submission","Not genotyped"))) | X13: =IF(K13="","",IF(COUNTIFS(Candidate_Parents!A:A,U13,Candidate_Parents!C:C,K13)+COUNTIFS(Candidate_Parents!A:A,U13,Candidate_Parents!D:D,K13)+COUNTIFS(Candidate_Parents!A:A,U13,Candidate_Parents!E:E,K13)>0,"Genotyped",IF(COUNTIFS(B:B,B13,C:C,K13,P:P,"<>Not received")>0,"In this submission","Not genotyped"))) | Y13: Targhee | Z13: Smith Ranch | AA13: =IF(H13="","",IFERROR(YEAR(IF(INDEX(Submissions!Q:Q,MATCH(B13,Submissions!A:A,0))="",TODAY(),INDEX(Submissions!Q:Q,MATCH(B13,Submissions!A:A,0))))-VALUE(LEFT(H13,4)),"")) | AB13: =IF(AA13="","",IF(AA13>=INDEX(Settings!B:B,MATCH("Proven_Min_Age",Settings!A:A,0)),"Y","N")) | AE13: =IF(IF(AC13<>"",AC13,IFERROR(INDEX(Submissions!U:U,MATCH(B13,Submissions!A:A,0))&"",""))="","",IF(AND(IFERROR(INDEX(Cost_Share!H:H,MATCH(IF(AC13<>"",AC13,IFERROR(INDEX(Submissions!U:U,MATCH(B13,Submissions!A:A,0))&"","")),Cost_Share!A:A,0))&"","")="Y",E13=""),"",IF(AC13<>"",AC13,IFERROR(INDEX(Submissions!U:U,MATCH(B13,Submissions!A:A,0))&"","")))) | AF13: =IF(AE13="","None",IF(AD13<>"",AD13,IF(AB13="Y","Full","Partial"))) | AG13: INV-P003-01
A14: P003-01-26008 | B14: P003-01 | C14: 26008 | D14: 840003307100008 | E14: 610014202626T008 | F14: NE05200008 | G14: F | H14: 2026 | I14: Offspring | J14: 23015 | L14: Y | M14: Y | N14: Y | O14: B2026-01 | P14: Complete | R14: =COUNTIF(Photos!A:A,A14) | T14: [Staff name] | U14: =IFERROR(INDEX(Submissions!B:B,MATCH(B14,Submissions!A:A,0))&"","") | V14: =IF(P14="Complete","Y","N") | W14: =IF(J14="","",IF(COUNTIFS(Candidate_Parents!A:A,U14,Candidate_Parents!C:C,J14)+COUNTIFS(Candidate_Parents!A:A,U14,Candidate_Parents!D:D,J14)+COUNTIFS(Candidate_Parents!A:A,U14,Candidate_Parents!E:E,J14)>0,"Genotyped",IF(COUNTIFS(B:B,B14,C:C,J14,P:P,"<>Not received")>0,"In this submission","Not genotyped"))) | X14: =IF(K14="","",IF(COUNTIFS(Candidate_Parents!A:A,U14,Candidate_Parents!C:C,K14)+COUNTIFS(Candidate_Parents!A:A,U14,Candidate_Parents!D:D,K14)+COUNTIFS(Candidate_Parents!A:A,U14,Candidate_Parents!E:E,K14)>0,"Genotyped",IF(COUNTIFS(B:B,B14,C:C,K14,P:P,"<>Not received")>0,"In this submission","Not genotyped"))) | Y14: Targhee | Z14: Smith Ranch | AA14: =IF(H14="","",IFERROR(YEAR(IF(INDEX(Submissions!Q:Q,MATCH(B14,Submissions!A:A,0))="",TODAY(),INDEX(Submissions!Q:Q,MATCH(B14,Submissions!A:A,0))))-VALUE(LEFT(H14,4)),"")) | AB14: =IF(AA14="","",IF(AA14>=INDEX(Settings!B:B,MATCH("Proven_Min_Age",Settings!A:A,0)),"Y","N")) | AE14: =IF(IF(AC14<>"",AC14,IFERROR(INDEX(Submissions!U:U,MATCH(B14,Submissions!A:A,0))&"",""))="","",IF(AND(IFERROR(INDEX(Cost_Share!H:H,MATCH(IF(AC14<>"",AC14,IFERROR(INDEX(Submissions!U:U,MATCH(B14,Submissions!A:A,0))&"","")),Cost_Share!A:A,0))&"","")="Y",E14=""),"",IF(AC14<>"",AC14,IFERROR(INDEX(Submissions!U:U,MATCH(B14,Submissions!A:A,0))&"","")))) | AF14: =IF(AE14="","None",IF(AD14<>"",AD14,IF(AB14="Y","Full","Partial"))) | AG14: INV-P003-01
A15: P003-01-26009 | B15: P003-01 | C15: 26009 | D15: 840003307100009 | E15: 610014202626T009 | F15: NE05200009 | G15: M | H15: 2026 | I15: Offspring | J15: 23015 | L15: Y | M15: Y | N15: Y | O15: B2026-01 | P15: Complete | R15: =COUNTIF(Photos!A:A,A15) | T15: [Staff name] | U15: =IFERROR(INDEX(Submissions!B:B,MATCH(B15,Submissions!A:A,0))&"","") | V15: =IF(P15="Complete","Y","N") | W15: =IF(J15="","",IF(COUNTIFS(Candidate_Parents!A:A,U15,Candidate_Parents!C:C,J15)+COUNTIFS(Candidate_Parents!A:A,U15,Candidate_Parents!D:D,J15)+COUNTIFS(Candidate_Parents!A:A,U15,Candidate_Parents!E:E,J15)>0,"Genotyped",IF(COUNTIFS(B:B,B15,C:C,J15,P:P,"<>Not received")>0,"In this submission","Not genotyped"))) | X15: =IF(K15="","",IF(COUNTIFS(Candidate_Parents!A:A,U15,Candidate_Parents!C:C,K15)+COUNTIFS(Candidate_Parents!A:A,U15,Candidate_Parents!D:D,K15)+COUNTIFS(Candidate_Parents!A:A,U15,Candidate_Parents!E:E,K15)>0,"Genotyped",IF(COUNTIFS(B:B,B15,C:C,K15,P:P,"<>Not received")>0,"In this submission","Not genotyped"))) | Y15: Targhee | Z15: Smith Ranch | AA15: =IF(H15="","",IFERROR(YEAR(IF(INDEX(Submissions!Q:Q,MATCH(B15,Submissions!A:A,0))="",TODAY(),INDEX(Submissions!Q:Q,MATCH(B15,Submissions!A:A,0))))-VALUE(LEFT(H15,4)),"")) | AB15: =IF(AA15="","",IF(AA15>=INDEX(Settings!B:B,MATCH("Proven_Min_Age",Settings!A:A,0)),"Y","N")) | AE15: =IF(IF(AC15<>"",AC15,IFERROR(INDEX(Submissions!U:U,MATCH(B15,Submissions!A:A,0))&"",""))="","",IF(AND(IFERROR(INDEX(Cost_Share!H:H,MATCH(IF(AC15<>"",AC15,IFERROR(INDEX(Submissions!U:U,MATCH(B15,Submissions!A:A,0))&"","")),Cost_Share!A:A,0))&"","")="Y",E15=""),"",IF(AC15<>"",AC15,IFERROR(INDEX(Submissions!U:U,MATCH(B15,Submissions!A:A,0))&"","")))) | AF15: =IF(AE15="","None",IF(AD15<>"",AD15,IF(AB15="Y","Full","Partial"))) | AG15: INV-P003-01
A16: P003-01-26010 | B16: P003-01 | C16: 26010 | D16: 840003307100010 | E16: 610014202626T010 | F16: NE05200010 | G16: F | H16: 2026 | I16: Offspring | J16: 23015 | L16: Y | M16: Y | N16: Y | O16: B2026-01 | P16: Complete | R16: =COUNTIF(Photos!A:A,A16) | T16: [Staff name] | U16: =IFERROR(INDEX(Submissions!B:B,MATCH(B16,Submissions!A:A,0))&"","") | V16: =IF(P16="Complete","Y","N") | W16: =IF(J16="","",IF(COUNTIFS(Candidate_Parents!A:A,U16,Candidate_Parents!C:C,J16)+COUNTIFS(Candidate_Parents!A:A,U16,Candidate_Parents!D:D,J16)+COUNTIFS(Candidate_Parents!A:A,U16,Candidate_Parents!E:E,J16)>0,"Genotyped",IF(COUNTIFS(B:B,B16,C:C,J16,P:P,"<>Not received")>0,"In this submission","Not genotyped"))) | X16: =IF(K16="","",IF(COUNTIFS(Candidate_Parents!A:A,U16,Candidate_Parents!C:C,K16)+COUNTIFS(Candidate_Parents!A:A,U16,Candidate_Parents!D:D,K16)+COUNTIFS(Candidate_Parents!A:A,U16,Candidate_Parents!E:E,K16)>0,"Genotyped",IF(COUNTIFS(B:B,B16,C:C,K16,P:P,"<>Not received")>0,"In this submission","Not genotyped"))) | Y16: Targhee | Z16: Smith Ranch | AA16: =IF(H16="","",IFERROR(YEAR(IF(INDEX(Submissions!Q:Q,MATCH(B16,Submissions!A:A,0))="",TODAY(),INDEX(Submissions!Q:Q,MATCH(B16,Submissions!A:A,0))))-VALUE(LEFT(H16,4)),"")) | AB16: =IF(AA16="","",IF(AA16>=INDEX(Settings!B:B,MATCH("Proven_Min_Age",Settings!A:A,0)),"Y","N")) | AE16: =IF(IF(AC16<>"",AC16,IFERROR(INDEX(Submissions!U:U,MATCH(B16,Submissions!A:A,0))&"",""))="","",IF(AND(IFERROR(INDEX(Cost_Share!H:H,MATCH(IF(AC16<>"",AC16,IFERROR(INDEX(Submissions!U:U,MATCH(B16,Submissions!A:A,0))&"","")),Cost_Share!A:A,0))&"","")="Y",E16=""),"",IF(AC16<>"",AC16,IFERROR(INDEX(Submissions!U:U,MATCH(B16,Submissions!A:A,0))&"","")))) | AF16: =IF(AE16="","None",IF(AD16<>"",AD16,IF(AB16="Y","Full","Partial"))) | AG16: INV-P003-01
A17: P003-01-23015 | B17: P003-01 | C17: 23015 | D17: 840003307100011 | E17: 610014202323T015 | F17: NE05200011 | G17: M | H17: 2023 | I17: Sire | L17: Y | M17: N | N17: Y | O17: B2026-02 | P17: Complete | R17: =COUNTIF(Photos!A:A,A17) | T17: [Staff name] | U17: =IFERROR(INDEX(Submissions!B:B,MATCH(B17,Submissions!A:A,0))&"","") | V17: =IF(P17="Complete","Y","N") | W17: =IF(J17="","",IF(COUNTIFS(Candidate_Parents!A:A,U17,Candidate_Parents!C:C,J17)+COUNTIFS(Candidate_Parents!A:A,U17,Candidate_Parents!D:D,J17)+COUNTIFS(Candidate_Parents!A:A,U17,Candidate_Parents!E:E,J17)>0,"Genotyped",IF(COUNTIFS(B:B,B17,C:C,J17,P:P,"<>Not received")>0,"In this submission","Not genotyped"))) | X17: =IF(K17="","",IF(COUNTIFS(Candidate_Parents!A:A,U17,Candidate_Parents!C:C,K17)+COUNTIFS(Candidate_Parents!A:A,U17,Candidate_Parents!D:D,K17)+COUNTIFS(Candidate_Parents!A:A,U17,Candidate_Parents!E:E,K17)>0,"Genotyped",IF(COUNTIFS(B:B,B17,C:C,K17,P:P,"<>Not received")>0,"In this submission","Not genotyped"))) | Y17: Targhee | Z17: Bar T Ranch | AA17: =IF(H17="","",IFERROR(YEAR(IF(INDEX(Submissions!Q:Q,MATCH(B17,Submissions!A:A,0))="",TODAY(),INDEX(Submissions!Q:Q,MATCH(B17,Submissions!A:A,0))))-VALUE(LEFT(H17,4)),"")) | AB17: =IF(AA17="","",IF(AA17>=INDEX(Settings!B:B,MATCH("Proven_Min_Age",Settings!A:A,0)),"Y","N")) | AE17: =IF(IF(AC17<>"",AC17,IFERROR(INDEX(Submissions!U:U,MATCH(B17,Submissions!A:A,0))&"",""))="","",IF(AND(IFERROR(INDEX(Cost_Share!H:H,MATCH(IF(AC17<>"",AC17,IFERROR(INDEX(Submissions!U:U,MATCH(B17,Submissions!A:A,0))&"","")),Cost_Share!A:A,0))&"","")="Y",E17=""),"",IF(AC17<>"",AC17,IFERROR(INDEX(Submissions!U:U,MATCH(B17,Submissions!A:A,0))&"","")))) | AF17: =IF(AE17="","None",IF(AD17<>"",AD17,IF(AB17="Y","Full","Partial"))) | AG17: INV-P003-01
A18: P003-01-0412 | B18: P003-01 | C18: 0412 | D18: 840003307100012 | F18: NE05200012 | G18: F | H18: 2018-2020 | I18: Dam | L18: Y | M18: N | N18: N | P18: Not received | R18: =COUNTIF(Photos!A:A,A18) | S18: Not in the package received; producer resending (P003-01-R1) | U18: =IFERROR(INDEX(Submissions!B:B,MATCH(B18,Submissions!A:A,0))&"","") | V18: =IF(P18="Complete","Y","N") | W18: =IF(J18="","",IF(COUNTIFS(Candidate_Parents!A:A,U18,Candidate_Parents!C:C,J18)+COUNTIFS(Candidate_Parents!A:A,U18,Candidate_Parents!D:D,J18)+COUNTIFS(Candidate_Parents!A:A,U18,Candidate_Parents!E:E,J18)>0,"Genotyped",IF(COUNTIFS(B:B,B18,C:C,J18,P:P,"<>Not received")>0,"In this submission","Not genotyped"))) | X18: =IF(K18="","",IF(COUNTIFS(Candidate_Parents!A:A,U18,Candidate_Parents!C:C,K18)+COUNTIFS(Candidate_Parents!A:A,U18,Candidate_Parents!D:D,K18)+COUNTIFS(Candidate_Parents!A:A,U18,Candidate_Parents!E:E,K18)>0,"Genotyped",IF(COUNTIFS(B:B,B18,C:C,K18,P:P,"<>Not received")>0,"In this submission","Not genotyped"))) | Y18: Targhee | Z18: Smith Ranch | AA18: =IF(H18="","",IFERROR(YEAR(IF(INDEX(Submissions!Q:Q,MATCH(B18,Submissions!A:A,0))="",TODAY(),INDEX(Submissions!Q:Q,MATCH(B18,Submissions!A:A,0))))-VALUE(LEFT(H18,4)),"")) | AB18: =IF(AA18="","",IF(AA18>=INDEX(Settings!B:B,MATCH("Proven_Min_Age",Settings!A:A,0)),"Y","N")) | AE18: =IF(IF(AC18<>"",AC18,IFERROR(INDEX(Submissions!U:U,MATCH(B18,Submissions!A:A,0))&"",""))="","",IF(AND(IFERROR(INDEX(Cost_Share!H:H,MATCH(IF(AC18<>"",AC18,IFERROR(INDEX(Submissions!U:U,MATCH(B18,Submissions!A:A,0))&"","")),Cost_Share!A:A,0))&"","")="Y",E18=""),"",IF(AC18<>"",AC18,IFERROR(INDEX(Submissions!U:U,MATCH(B18,Submissions!A:A,0))&"","")))) | AF18: =IF(AE18="","None",IF(AD18<>"",AD18,IF(AB18="Y","Full","Partial")))
A19: P004-01-J01 | B19: P004-01 | C19: J01 | D19: 840003307300001 | F19: NE05200201 | G19: M | H19: 2023 | I19: Sire | L19: Y | M19: Y | P19: Awaiting sample | R19: =COUNTIF(Photos!A:A,A19) | U19: =IFERROR(INDEX(Submissions!B:B,MATCH(B19,Submissions!A:A,0))&"","") | V19: =IF(P19="Complete","Y","N") | W19: =IF(J19="","",IF(COUNTIFS(Candidate_Parents!A:A,U19,Candidate_Parents!C:C,J19)+COUNTIFS(Candidate_Parents!A:A,U19,Candidate_Parents!D:D,J19)+COUNTIFS(Candidate_Parents!A:A,U19,Candidate_Parents!E:E,J19)>0,"Genotyped",IF(COUNTIFS(B:B,B19,C:C,J19,P:P,"<>Not received")>0,"In this submission","Not genotyped"))) | X19: =IF(K19="","",IF(COUNTIFS(Candidate_Parents!A:A,U19,Candidate_Parents!C:C,K19)+COUNTIFS(Candidate_Parents!A:A,U19,Candidate_Parents!D:D,K19)+COUNTIFS(Candidate_Parents!A:A,U19,Candidate_Parents!E:E,K19)>0,"Genotyped",IF(COUNTIFS(B:B,B19,C:C,K19,P:P,"<>Not received")>0,"In this submission","Not genotyped"))) | Y19: Columbia | Z19: Jones Sheep Co | AA19: =IF(H19="","",IFERROR(YEAR(IF(INDEX(Submissions!Q:Q,MATCH(B19,Submissions!A:A,0))="",TODAY(),INDEX(Submissions!Q:Q,MATCH(B19,Submissions!A:A,0))))-VALUE(LEFT(H19,4)),"")) | AB19: =IF(AA19="","",IF(AA19>=INDEX(Settings!B:B,MATCH("Proven_Min_Age",Settings!A:A,0)),"Y","N")) | AE19: =IF(IF(AC19<>"",AC19,IFERROR(INDEX(Submissions!U:U,MATCH(B19,Submissions!A:A,0))&"",""))="","",IF(AND(IFERROR(INDEX(Cost_Share!H:H,MATCH(IF(AC19<>"",AC19,IFERROR(INDEX(Submissions!U:U,MATCH(B19,Submissions!A:A,0))&"","")),Cost_Share!A:A,0))&"","")="Y",E19=""),"",IF(AC19<>"",AC19,IFERROR(INDEX(Submissions!U:U,MATCH(B19,Submissions!A:A,0))&"","")))) | AF19: =IF(AE19="","None",IF(AD19<>"",AD19,IF(AB19="Y","Full","Partial")))
A20: P004-01-J02 | B20: P004-01 | C20: J02 | D20: 840003307300002 | F20: NE05200202 | G20: F | H20: 2022 | I20: Dam | L20: Y | M20: Y | P20: Awaiting sample | R20: =COUNTIF(Photos!A:A,A20) | U20: =IFERROR(INDEX(Submissions!B:B,MATCH(B20,Submissions!A:A,0))&"","") | V20: =IF(P20="Complete","Y","N") | W20: =IF(J20="","",IF(COUNTIFS(Candidate_Parents!A:A,U20,Candidate_Parents!C:C,J20)+COUNTIFS(Candidate_Parents!A:A,U20,Candidate_Parents!D:D,J20)+COUNTIFS(Candidate_Parents!A:A,U20,Candidate_Parents!E:E,J20)>0,"Genotyped",IF(COUNTIFS(B:B,B20,C:C,J20,P:P,"<>Not received")>0,"In this submission","Not genotyped"))) | X20: =IF(K20="","",IF(COUNTIFS(Candidate_Parents!A:A,U20,Candidate_Parents!C:C,K20)+COUNTIFS(Candidate_Parents!A:A,U20,Candidate_Parents!D:D,K20)+COUNTIFS(Candidate_Parents!A:A,U20,Candidate_Parents!E:E,K20)>0,"Genotyped",IF(COUNTIFS(B:B,B20,C:C,K20,P:P,"<>Not received")>0,"In this submission","Not genotyped"))) | Y20: Columbia | Z20: Jones Sheep Co | AA20: =IF(H20="","",IFERROR(YEAR(IF(INDEX(Submissions!Q:Q,MATCH(B20,Submissions!A:A,0))="",TODAY(),INDEX(Submissions!Q:Q,MATCH(B20,Submissions!A:A,0))))-VALUE(LEFT(H20,4)),"")) | AB20: =IF(AA20="","",IF(AA20>=INDEX(Settings!B:B,MATCH("Proven_Min_Age",Settings!A:A,0)),"Y","N")) | AE20: =IF(IF(AC20<>"",AC20,IFERROR(INDEX(Submissions!U:U,MATCH(B20,Submissions!A:A,0))&"",""))="","",IF(AND(IFERROR(INDEX(Cost_Share!H:H,MATCH(IF(AC20<>"",AC20,IFERROR(INDEX(Submissions!U:U,MATCH(B20,Submissions!A:A,0))&"","")),Cost_Share!A:A,0))&"","")="Y",E20=""),"",IF(AC20<>"",AC20,IFERROR(INDEX(Submissions!U:U,MATCH(B20,Submissions!A:A,0))&"","")))) | AF20: =IF(AE20="","None",IF(AD20<>"",AD20,IF(AB20="Y","Full","Partial")))
A21: P004-01-J03 | B21: P004-01 | C21: J03 | D21: 840003307300003 | F21: NE05200203 | G21: F | H21: 2026 | I21: Offspring | J21: J01 | K21: J02 | L21: Y | M21: Y | P21: Awaiting sample | R21: =COUNTIF(Photos!A:A,A21) | U21: =IFERROR(INDEX(Submissions!B:B,MATCH(B21,Submissions!A:A,0))&"","") | V21: =IF(P21="Complete","Y","N") | W21: =IF(J21="","",IF(COUNTIFS(Candidate_Parents!A:A,U21,Candidate_Parents!C:C,J21)+COUNTIFS(Candidate_Parents!A:A,U21,Candidate_Parents!D:D,J21)+COUNTIFS(Candidate_Parents!A:A,U21,Candidate_Parents!E:E,J21)>0,"Genotyped",IF(COUNTIFS(B:B,B21,C:C,J21,P:P,"<>Not received")>0,"In this submission","Not genotyped"))) | X21: =IF(K21="","",IF(COUNTIFS(Candidate_Parents!A:A,U21,Candidate_Parents!C:C,K21)+COUNTIFS(Candidate_Parents!A:A,U21,Candidate_Parents!D:D,K21)+COUNTIFS(Candidate_Parents!A:A,U21,Candidate_Parents!E:E,K21)>0,"Genotyped",IF(COUNTIFS(B:B,B21,C:C,K21,P:P,"<>Not received")>0,"In this submission","Not genotyped"))) | Y21: Columbia | Z21: Jones Sheep Co | AA21: =IF(H21="","",IFERROR(YEAR(IF(INDEX(Submissions!Q:Q,MATCH(B21,Submissions!A:A,0))="",TODAY(),INDEX(Submissions!Q:Q,MATCH(B21,Submissions!A:A,0))))-VALUE(LEFT(H21,4)),"")) | AB21: =IF(AA21="","",IF(AA21>=INDEX(Settings!B:B,MATCH("Proven_Min_Age",Settings!A:A,0)),"Y","N")) | AE21: =IF(IF(AC21<>"",AC21,IFERROR(INDEX(Submissions!U:U,MATCH(B21,Submissions!A:A,0))&"",""))="","",IF(AND(IFERROR(INDEX(Cost_Share!H:H,MATCH(IF(AC21<>"",AC21,IFERROR(INDEX(Submissions!U:U,MATCH(B21,Submissions!A:A,0))&"","")),Cost_Share!A:A,0))&"","")="Y",E21=""),"",IF(AC21<>"",AC21,IFERROR(INDEX(Submissions!U:U,MATCH(B21,Submissions!A:A,0))&"","")))) | AF21: =IF(AE21="","None",IF(AD21<>"",AD21,IF(AB21="Y","Full","Partial")))
A22: P004-01-J04 | B22: P004-01 | C22: J04 | D22: 840003307300004 | F22: NE05200204 | G22: M | H22: 2026 | I22: Offspring | J22: J01 | K22: J02 | L22: Y | M22: Y | P22: Awaiting sample | R22: =COUNTIF(Photos!A:A,A22) | U22: =IFERROR(INDEX(Submissions!B:B,MATCH(B22,Submissions!A:A,0))&"","") | V22: =IF(P22="Complete","Y","N") | W22: =IF(J22="","",IF(COUNTIFS(Candidate_Parents!A:A,U22,Candidate_Parents!C:C,J22)+COUNTIFS(Candidate_Parents!A:A,U22,Candidate_Parents!D:D,J22)+COUNTIFS(Candidate_Parents!A:A,U22,Candidate_Parents!E:E,J22)>0,"Genotyped",IF(COUNTIFS(B:B,B22,C:C,J22,P:P,"<>Not received")>0,"In this submission","Not genotyped"))) | X22: =IF(K22="","",IF(COUNTIFS(Candidate_Parents!A:A,U22,Candidate_Parents!C:C,K22)+COUNTIFS(Candidate_Parents!A:A,U22,Candidate_Parents!D:D,K22)+COUNTIFS(Candidate_Parents!A:A,U22,Candidate_Parents!E:E,K22)>0,"Genotyped",IF(COUNTIFS(B:B,B22,C:C,K22,P:P,"<>Not received")>0,"In this submission","Not genotyped"))) | Y22: Columbia | Z22: Jones Sheep Co | AA22: =IF(H22="","",IFERROR(YEAR(IF(INDEX(Submissions!Q:Q,MATCH(B22,Submissions!A:A,0))="",TODAY(),INDEX(Submissions!Q:Q,MATCH(B22,Submissions!A:A,0))))-VALUE(LEFT(H22,4)),"")) | AB22: =IF(AA22="","",IF(AA22>=INDEX(Settings!B:B,MATCH("Proven_Min_Age",Settings!A:A,0)),"Y","N")) | AE22: =IF(IF(AC22<>"",AC22,IFERROR(INDEX(Submissions!U:U,MATCH(B22,Submissions!A:A,0))&"",""))="","",IF(AND(IFERROR(INDEX(Cost_Share!H:H,MATCH(IF(AC22<>"",AC22,IFERROR(INDEX(Submissions!U:U,MATCH(B22,Submissions!A:A,0))&"","")),Cost_Share!A:A,0))&"","")="Y",E22=""),"",IF(AC22<>"",AC22,IFERROR(INDEX(Submissions!U:U,MATCH(B22,Submissions!A:A,0))&"","")))) | AF22: =IF(AE22="","None",IF(AD22<>"",AD22,IF(AB22="Y","Full","Partial")))
A23: P004-01-J05 | B23: P004-01 | C23: J05 | D23: 840003307300005 | F23: NE05200205 | G23: F | H23: 2026 | I23: Offspring | J23: J01 | K23: J02 | L23: Y | M23: Y | P23: Awaiting sample | R23: =COUNTIF(Photos!A:A,A23) | U23: =IFERROR(INDEX(Submissions!B:B,MATCH(B23,Submissions!A:A,0))&"","") | V23: =IF(P23="Complete","Y","N") | W23: =IF(J23="","",IF(COUNTIFS(Candidate_Parents!A:A,U23,Candidate_Parents!C:C,J23)+COUNTIFS(Candidate_Parents!A:A,U23,Candidate_Parents!D:D,J23)+COUNTIFS(Candidate_Parents!A:A,U23,Candidate_Parents!E:E,J23)>0,"Genotyped",IF(COUNTIFS(B:B,B23,C:C,J23,P:P,"<>Not received")>0,"In this submission","Not genotyped"))) | X23: =IF(K23="","",IF(COUNTIFS(Candidate_Parents!A:A,U23,Candidate_Parents!C:C,K23)+COUNTIFS(Candidate_Parents!A:A,U23,Candidate_Parents!D:D,K23)+COUNTIFS(Candidate_Parents!A:A,U23,Candidate_Parents!E:E,K23)>0,"Genotyped",IF(COUNTIFS(B:B,B23,C:C,K23,P:P,"<>Not received")>0,"In this submission","Not genotyped"))) | Y23: Columbia | Z23: Jones Sheep Co | AA23: =IF(H23="","",IFERROR(YEAR(IF(INDEX(Submissions!Q:Q,MATCH(B23,Submissions!A:A,0))="",TODAY(),INDEX(Submissions!Q:Q,MATCH(B23,Submissions!A:A,0))))-VALUE(LEFT(H23,4)),"")) | AB23: =IF(AA23="","",IF(AA23>=INDEX(Settings!B:B,MATCH("Proven_Min_Age",Settings!A:A,0)),"Y","N")) | AE23: =IF(IF(AC23<>"",AC23,IFERROR(INDEX(Submissions!U:U,MATCH(B23,Submissions!A:A,0))&"",""))="","",IF(AND(IFERROR(INDEX(Cost_Share!H:H,MATCH(IF(AC23<>"",AC23,IFERROR(INDEX(Submissions!U:U,MATCH(B23,Submissions!A:A,0))&"","")),Cost_Share!A:A,0))&"","")="Y",E23=""),"",IF(AC23<>"",AC23,IFERROR(INDEX(Submissions!U:U,MATCH(B23,Submissions!A:A,0))&"","")))) | AF23: =IF(AE23="","None",IF(AD23<>"",AD23,IF(AB23="Y","Full","Partial")))
A24: P004-01-J06 | B24: P004-01 | C24: J06 | D24: 840003307300006 | F24: NE05200206 | G24: F | H24: 2025 | I24: Offspring | J24: J01 | K24: J02 | L24: Y | M24: Y | P24: Awaiting sample | R24: =COUNTIF(Photos!A:A,A24) | U24: =IFERROR(INDEX(Submissions!B:B,MATCH(B24,Submissions!A:A,0))&"","") | V24: =IF(P24="Complete","Y","N") | W24: =IF(J24="","",IF(COUNTIFS(Candidate_Parents!A:A,U24,Candidate_Parents!C:C,J24)+COUNTIFS(Candidate_Parents!A:A,U24,Candidate_Parents!D:D,J24)+COUNTIFS(Candidate_Parents!A:A,U24,Candidate_Parents!E:E,J24)>0,"Genotyped",IF(COUNTIFS(B:B,B24,C:C,J24,P:P,"<>Not received")>0,"In this submission","Not genotyped"))) | X24: =IF(K24="","",IF(COUNTIFS(Candidate_Parents!A:A,U24,Candidate_Parents!C:C,K24)+COUNTIFS(Candidate_Parents!A:A,U24,Candidate_Parents!D:D,K24)+COUNTIFS(Candidate_Parents!A:A,U24,Candidate_Parents!E:E,K24)>0,"Genotyped",IF(COUNTIFS(B:B,B24,C:C,K24,P:P,"<>Not received")>0,"In this submission","Not genotyped"))) | Y24: Columbia | Z24: Jones Sheep Co | AA24: =IF(H24="","",IFERROR(YEAR(IF(INDEX(Submissions!Q:Q,MATCH(B24,Submissions!A:A,0))="",TODAY(),INDEX(Submissions!Q:Q,MATCH(B24,Submissions!A:A,0))))-VALUE(LEFT(H24,4)),"")) | AB24: =IF(AA24="","",IF(AA24>=INDEX(Settings!B:B,MATCH("Proven_Min_Age",Settings!A:A,0)),"Y","N")) | AE24: =IF(IF(AC24<>"",AC24,IFERROR(INDEX(Submissions!U:U,MATCH(B24,Submissions!A:A,0))&"",""))="","",IF(AND(IFERROR(INDEX(Cost_Share!H:H,MATCH(IF(AC24<>"",AC24,IFERROR(INDEX(Submissions!U:U,MATCH(B24,Submissions!A:A,0))&"","")),Cost_Share!A:A,0))&"","")="Y",E24=""),"",IF(AC24<>"",AC24,IFERROR(INDEX(Submissions!U:U,MATCH(B24,Submissions!A:A,0))&"","")))) | AF24: =IF(AE24="","None",IF(AD24<>"",AD24,IF(AB24="Y","Full","Partial")))

Sheet Photos
A1: Animal_Key | B1: Submission_ID | C1: Photo_No | D1: Drive_Link | E1: Uploaded_Date | F1: Archived_Date | G1: Archive_Location
A2: P004-01-J01 | B2: P004-01 | C2: 1 | D2: [Drive link] | E2: 46296
A3: P004-01-J01 | B3: P004-01 | C3: 2 | D3: [Drive link] | E3: 46296
A4: P004-01-J02 | B4: P004-01 | C4: 1 | D4: [Drive link] | E4: 46296
A5: P004-01-J03 | B5: P004-01 | C5: 1 | D5: [Drive link] | E5: 46296
A6: P004-01-J03 | B6: P004-01 | C6: 2 | D6: [Drive link] | E6: 46296
A7: P004-01-J03 | B7: P004-01 | C7: 3 | D7: [Drive link] | E7: 46296
A8: P004-01-J04 | B8: P004-01 | C8: 1 | D8: [Drive link] | E8: 46296
A9: P004-01-J05 | B9: P004-01 | C9: 1 | D9: [Drive link] | E9: 46296
A10: P004-01-J06 | B10: P004-01 | C10: 1 | D10: [Drive link] | E10: 46296
A11: P004-01-J06 | B11: P004-01 | C11: 2 | D11: [Drive link] | E11: 46296

Sheet Batches
A1: Batch_ID | B1: Lab | C1: Status | D1: Created_Date | E1: Created_By | F1: Shipped_Date | G1: Samples | H1: Results_Received_Date | I1: Export_File | J1: Notes
A2: B2026-01 | B2: GenomNZ | C2: Results in | D2: 46302 | E2: [Staff name] | F2: 46303 | G2: =COUNTIF(Animals!O:O,A2)+COUNTIF(Replacements!G:G,A2) | H2: 46319 | I2: [Drive link to B2026-01_GenomNZ.xlsx]
A3: B2026-02 | B3: GenomNZ | C3: Results in | D3: 46315 | E3: [Staff name] | F3: 46316 | G3: =COUNTIF(Animals!O:O,A3)+COUNTIF(Replacements!G:G,A3) | H3: 46322 | I3: [Drive link to B2026-02_GenomNZ.xlsx]

Sheet Replacements
A1: Replacement_ID | B1: Animal_Key | C1: Submission_ID | D1: Reason | E1: Original_TSU | F1: New_TSU | G1: Original_Batch | H1: Requested_Date | I1: Received | J1: Received_Date | K1: Received_By | L1: New_Batch | M1: Notes
A2: P003-01-R1 | B2: P003-01-26007 | C2: P003-01 | D2: Failed QC | E2: NE05200007 | F2: NE05200099 | G2: B2026-01 | H2: 46324 | M2: New TSU
A3: P003-01-R1 | B3: P003-01-0412 | C3: P003-01 | D3: Not received | E3: NE05200012 | F3: NE05200012 | H3: 46324 | M3: Sending the original TSU

Sheet Conditions
A1: Condition_ID | B1: Display_Name | C1: Gene_Marker | D1: Show_On_Web | E1: Active | F1: Sort_Order | G1: Call_Is | H1: Explanation
A2: SCRAPIE | B2: Scrapie susceptibility | C2: PRNP (codons 136, 154, 171) | D2: Y | E2: Y | F2: 1 | G2: Codon 171 pair (RR, QR, HR, QQ) | H2: Shown as codons 136, 154 and 171 for each copy (for example ARR/ARQ). Codon 171 is most significant and used most commonly: RR animals are the least susceptible to scrapie, QR carry one susceptible copy, and QQ animals are most susceptible.
A3: OPP | B3: OPP susceptibility | C3: TMEM154 | D3: Y | E3: Y | F3: 2 | G3: Diplotype (1/1, 1/3, ...) | H3: Two haplotypes per animal. Haplotype 1 is associated with lower susceptibility to ovine progressive pneumonia (OPP); haplotypes 2 and 3 with higher susceptibility. 1/1 animals are in the lowest-risk group.
A4: COND3 | B4: [Condition 3] | C4: [Gene or marker] | D4: N | E4: N | F4: 3 | G4: [What R writes as the call] | H4: [What the test shows and how to read each result.]

Sheet Result_Key
A1: Key | B1: Condition_ID | C1: Call | D1: Result_Label | E1: Category | F1: Meaning
A2: =B2&"|"&C2 | B2: SCRAPIE | C2: RR | D2: Least susceptible | E2: good | F2: Two resistant copies at codon 171.
A3: =B3&"|"&C3 | B3: SCRAPIE | C3: QR | D3: Carries Q | E3: mid | F3: One resistant and one susceptible copy.
A4: =B4&"|"&C4 | B4: SCRAPIE | C4: HR | D4: Carries H | E4: mid | F4: One resistant copy and one H copy.
A5: =B5&"|"&C5 | B5: SCRAPIE | C5: QQ | D5: More susceptible | E5: bad | F5: Two susceptible copies.
A6: =B6&"|"&C6 | B6: OPP | C6: 1/1 | D6: Lower risk | E6: good | F6: Two copies of haplotype 1.
A7: =B7&"|"&C7 | B7: OPP | C7: 1/2 | D7: Moderate risk | E7: mid | F7: One copy of haplotype 1.
A8: =B8&"|"&C8 | B8: OPP | C8: 1/3 | D8: Moderate risk | E8: mid | F8: One copy of haplotype 1.
A9: =B9&"|"&C9 | B9: OPP | C9: 2/2 | D9: Higher risk | E9: bad | F9: No copies of haplotype 1.
A10: =B10&"|"&C10 | B10: OPP | C10: 2/3 | D10: Higher risk | E10: bad | F10: No copies of haplotype 1.
A11: =B11&"|"&C11 | B11: OPP | C11: 3/3 | D11: Higher risk | E11: bad | F11: No copies of haplotype 1.
A12: =B12&"|"&C12 | B12: COND3 | C12: [call] | D12: [Clear] | E12: good | F12: [ ]
A13: =B13&"|"&C13 | B13: COND3 | C13: [call] | D13: [Carrier] | E13: mid | F13: [ ]
A14: =B14&"|"&C14 | B14: COND3 | C14: [call] | D14: [Affected] | E14: bad | F14: [ ]

Sheet Results
A1: Animal_Key | B1: Submission_ID | C1: Condition_ID | D1: Genotype | E1: Call | F1: Result_Label | G1: Category | H1: Batch | I1: Run_Date | J1: Released
A2: P003-01-26001 | B2: P003-01 | C2: SCRAPIE | D2: ARR/ARQ | E2: QR | F2: Carries Q | G2: mid | H2: B2026-01 | I2: 46319 | J2: Y
A3: P003-01-26001 | B3: P003-01 | C3: OPP | D3: 1/1 | E3: 1/1 | F3: Lower risk | G3: good | H3: B2026-01 | I3: 46319 | J3: Y
A4: P003-01-26002 | B4: P003-01 | C4: SCRAPIE | D4: ARR/ARR | E4: RR | F4: Least susceptible | G4: good | H4: B2026-01 | I4: 46319 | J4: Y
A5: P003-01-26002 | B5: P003-01 | C5: OPP | D5: 2/3 | E5: 2/3 | F5: Higher risk | G5: bad | H5: B2026-01 | I5: 46319 | J5: Y
A6: P003-01-26003 | B6: P003-01 | C6: SCRAPIE | D6: ARR/ARQ | E6: QR | F6: Carries Q | G6: mid | H6: B2026-01 | I6: 46319 | J6: Y
A7: P003-01-26003 | B7: P003-01 | C7: OPP | D7: 1/1 | E7: 1/1 | F7: Lower risk | G7: good | H7: B2026-01 | I7: 46319 | J7: Y
A8: P003-01-26004 | B8: P003-01 | C8: SCRAPIE | D8: ARR/ARH | E8: HR | F8: Carries H | G8: mid | H8: B2026-01 | I8: 46319 | J8: Y
A9: P003-01-26004 | B9: P003-01 | C9: OPP | D9: 1/3 | E9: 1/3 | F9: Moderate risk | G9: mid | H9: B2026-01 | I9: 46319 | J9: Y
A10: P003-01-26005 | B10: P003-01 | C10: SCRAPIE | D10: ARR/ARR | E10: RR | F10: Least susceptible | G10: good | H10: B2026-01 | I10: 46319 | J10: Y
A11: P003-01-26005 | B11: P003-01 | C11: OPP | D11: 3/3 | E11: 3/3 | F11: Higher risk | G11: bad | H11: B2026-01 | I11: 46319 | J11: Y
A12: P003-01-26006 | B12: P003-01 | C12: SCRAPIE | D12: ARR/ARR | E12: RR | F12: Least susceptible | G12: good | H12: B2026-01 | I12: 46319 | J12: Y
A13: P003-01-26006 | B13: P003-01 | C13: OPP | D13: 1/1 | E13: 1/1 | F13: Lower risk | G13: good | H13: B2026-01 | I13: 46319 | J13: Y
... A21: P003-01-23015 | B21: P003-01 | C21: OPP | D21: 1/1 | E21: 1/1 | F21: Lower risk | G21: good | H21: B2026-02 | I21: 46322 | J21: Y

Sheet Parentage
A1: Animal_Key | B1: Submission_ID | C1: Reported_Sire | D1: Sire_Result | E1: Sire_Assigned | F1: Reported_Dam | G1: Dam_Result | H1: Dam_Assigned | I1: Notes | J1: Released
A2: P003-01-26001 | B2: P003-01 | C2: 23015 | D2: Confirmed | E2: 610014202323T015 | G2: Not genotyped | J2: Y
A3: P003-01-26002 | B3: P003-01 | C3: 23015 | D3: Confirmed | E3: 610014202323T015 | G3: Not genotyped | J3: Y
A4: P003-01-26003 | B4: P003-01 | C4: 23015 | D4: Confirmed | E4: 610014202323T015 | G4: Not genotyped | J4: Y
A5: P003-01-26004 | B5: P003-01 | C5: 23015 | D5: Confirmed | E5: 610014202323T015 | G5: Not genotyped | J5: Y
A6: P003-01-26005 | B6: P003-01 | C6: 23015 | D6: Confirmed | E6: 610014202323T015 | G6: Not genotyped | J6: Y
A7: P003-01-26006 | B7: P003-01 | C7: 23015 | D7: Confirmed | E7: 610014202323T015 | G7: Not genotyped | J7: Y
A8: P003-01-26007 | B8: P003-01 | C8: 23015 | D8: Pending | G8: Pending | I8: Waiting on a new TSU | J8: N
A9: P003-01-26008 | B9: P003-01 | C9: 23015 | D9: Confirmed | E9: 610014202323T015 | G9: Not genotyped | J9: Y
A10: P003-01-26009 | B10: P003-01 | C10: 23015 | D10: Excluded | G10: Not genotyped | I10: No genotyped sire matched | J10: Y
A11: P003-01-26010 | B11: P003-01 | C11: 23015 | D11: Confirmed | E11: 610014202323T015 | G11: Not genotyped | J11: Y

Sheet Candidate_Parents
